Workbook

Sheet A̳ssets
B3: Paleta de Cores
B5: # 9BC848 | C5: Xbox Color | E5: # E8E6E9 | F5: negative zone
B6: # 22C55E | C6: Xbox Color
B7: # 2AE6B1 | C7: Menus
B8: # 5BF6A8 | C8: Menus
B12: Logos | J12: ícones

Sheet B̳ases
A1: Subscriber ID | B1: Name | C1: Plan | D1: Start Date | E1: Auto Renewal | F1: Subscription Price | G1: Subscription Type | H1: EA Play Season Pass | I1: EA Play Season Pass Price | J1: Minecraft Season Pass | K1: Minecraft Season Pass Price | L1: Coupon Value | M1: Total Value
A2: 3231 | B2: João Silva | C2: Ultimate | D2: 45292 | E2: Yes | F2: 15 | G2: Monthly | H2: Yes | I2: 30 | J2: Yes | K2: 20 | L2: 5 | M2: 60
A3: 3232 | B3: Maria Oliveira | C3: Core | D3: 45306 | E3: No | F3: 5 | G3: Annual | H3: No | I3: - | J3: No | K3: 0 | L3: 0 | M3: 5
A4: 3233 | B4: Lucas Fernandes | C4: Standard | D4: 45332 | E4: Yes | F4: 10 | G4: Quarterly | H4: No | I4: - | J4: Yes | K4: 20 | L4: 10 | M4: 20
A5: 3234 | B5: Ana Souza | C5: Ultimate | D5: 45342 | E5: No | F5: 15 | G5: Monthly | H5: Yes | I5: 30 | J5: Yes | K5: 20 | L5: 3 | M5: 62
A6: 3235 | B6: Pedro Gonçalves | C6: Core | D6: 45356 | E6: Yes | F6: 5 | G6: Monthly | H6: No | I6: - | J6: No | K6: 0 | L6: 1 | M6: 4
A7: 3236 | B7: Felipe Costa | C7: Standard | D7: 45353 | E7: No | F7: 10 | G7: Monthly | H7: No | I7: - | J7: Yes | K7: 20 | L7: 2 | M7: 28
A8: 3237 | B8: Camila Ribeiro | C8: Ultimate | D8: 45354 | E8: Yes | F8: 15 | G8: Quarterly | H8: Yes | I8: 30 | J8: Yes | K8: 20 | L8: 10 | M8: 55
A9: 3238 | B9: André Mendes | C9: Core | D9: 45355 | E9: Yes | F9: 5 | G9: Annual | H9: No | I9: - | J9: No | K9: 0 | L9: 0 | M9: 5
A10: 3239 | B10: Sofia Almeida | C10: Ultimate | D10: 45356 | E10: No | F10: 15 | G10: Monthly | H10: Yes | I10: 30 | J10: Yes | K10: 20 | L10: 5 | M10: 60
A11: 3240 | B11: Bruno Martins | C11: Standard | D11: 45357 | E11: Yes | F11: 10 | G11: Quarterly | H11: No | I11: - | J11: Yes | K11: 20 | L11: 15 | M11: 15
A12: 3241 | B12: Rita Castro | C12: Core | D12: 45358 | E12: No | F12: 5 | G12: Monthly | H12: No | I12: - | J12: No | K12: 0 | L12: 1 | M12: 4
A13: 3242 | B13: Marco Túlio | C13: Ultimate | D13: 45359 | E13: Yes | F13: 15 | G13: Annual | H13: Yes | I13: 30 | J13: Yes | K13: 20 | L13: 20 | M13: 45
A14: 3243 | B14: Lívia Silveira | C14: Standard | D14: 45360 | E14: No | F14: 10 | G14: Monthly | H14: No | I14: - | J14: Yes | K14: 20 | L14: 10 | M14: 20
A15: 3244 | B15: Diogo Sousa | C15: Core | D15: 45361 | E15: Yes | F15: 5 | G15: Quarterly | H15: No | I15: - | J15: No | K15: 0 | L15: 0 | M15: 5
A16: 3245 | B16: Fernanda Lima | C16: Ultimate | D16: 45362 | E16: No | F16: 15 | G16: Monthly | H16: Yes | I16: 30 | J16: Yes | K16: 20 | L16: 8 | M16: 57
A17: 3246 | B17: Caio Pereira | C17: Standard | D17: 45363 | E17: Yes | F17: 10 | G17: Annual | H17: No | I17: - | J17: Yes | K17: 20 | L17: 12 | M17: 18
A18: 3247 | B18: Beatriz Gomes | C18: Core | D18: 45364 | E18: No | F18: 5 | G18: Monthly | H18: No | I18: - | J18: No | K18: 0 | L18: 2 | M18: 3
A19: 3248 | B19: Cesar Oliveira | C19: Ultimate | D19: 45365 | E19: Yes | F19: 15 | G19: Quarterly | H19: Yes | I19: 30 | J19: Yes | K19: 20 | L19: 7 | M19: 58
A20: 3249 | B20: Débora Machado | C20: Standard | D20: 45366 | E20: No | F20: 10 | G20: Monthly | H20: No | I20: - | J20: Yes | K20: 20 | L20: 5 | M20: 25
A21: 3250 | B21: Eduardo Vargas | C21: Core | D21: 45367 | E21: Yes | F21: 5 | G21: Annual | H21: No | I21: - | J21: No | K21: 0 | L21: 0 | M21: 5
A22: 3251 | B22: Gabriela Santos | C22: Ultimate | D22: 45368 | E22: No | F22: 15 | G22: Monthly | H22: Yes | I22: 30 | J22: Yes | K22: 20 | L22: 3 | M22: 62
A23: 3252 | B23: Henrique Dias | C23: Standard | D23: 45369 | E23: Yes | F23: 10 | G23: Quarterly | H23: No | I23: - | J23: Yes | K23: 20 | L23: 15 | M23: 15
A24: 3253 | B24: Isabela Moreira | C24: Core | D24: 45370 | E24: No | F24: 5 | G24: Monthly | H24: No | I24: - | J24: No | K24: 0 | L24: 1 | M24: 4
A25: 3254 | B25: Joaquim Barbosa | C25: Ultimate | D25: 45371 | E25: Yes | F25: 15 | G25: Annual | H25: Yes | I25: 30 | J25: Yes | K25: 20 | L25: 20 | M25: 45
A26: 3255 | B26: Lara Rocha | C26: Standard | D26: 45372 | E26: No | F26: 10 | G26: Monthly | H26: No | I26: - | J26: Yes | K26: 20 | L26: 10 | M26: 20
A27: 3256 | B27: Matheus Silva | C27: Core | D27: 45373 | E27: Yes | F27: 5 | G27: Quarterly | H27: No | I27: - | J27: No | K27: 0 | L27: 0 | M27: 5
A28: 3257 | B28: Nicole Costa | C28: Ultimate | D28: 45374 | E28: No | F28: 15 | G28: Monthly | H28: Yes | I28: 30 | J28: Yes | K28: 20 | L28: 5 | M28: 60
A29: 3258 | B29: Otávio Mendonça | C29: Standard | D29: 45375 | E29: Yes | F29: 10 | G29: Annual | H29: No | I29: - | J29: Yes | K29: 20 | L29: 15 | M29: 15
A30: 3259 | B30: Paula Ferreira | C30: Core | D30: 45376 | E30: No | F30: 5 | G30: Monthly | H30: No | I30: - | J30: No | K30: 0 | L30: 1 | M30: 4
A31: 3260 | B31: Raquel Alves | C31: Ultimate | D31: 45377 | E31: Yes | F31: 15 | G31: Quarterly | H31: Yes | I31: 30 | J31: Yes | K31: 20 | L31: 7 | M31: 58
A32: 3261 | B32: Samuel Pires | C32: Standard | D32: 45378 | E32: No | F32: 10 | G32: Monthly | H32: No | I32: - | J32: Yes | K32: 20 | L32: 10 | M32: 20
A33: 3262 | B33: Tânia Barros | C33: Core | D33: 45379 | E33: Yes | F33: 5 | G33: Annual | H33: No | I33: - | J33: No | K33: 0 | L33: 0 | M33: 5
A34: 3263 | B34: Vinicius Lima | C34: Ultimate | D34: 45380 | E34: No | F34: 15 | G34: Monthly | H34: Yes | I34: 30 | J34: Yes | K34: 20 | L34: 3 | M34: 62
A35: 3264 | B35: Yasmin Teixeira | C35: Standard | D35: 45381 | E35: Yes | F35: 10 | G35: Quarterly | H35: No | I35: - | J35: Yes | K35: 20 | L35: 15 | M35: 15
A36: 3265 | B36: Zé Carlos | C36: Core | D36: 45382 | E36: No | F36: 5 | G36: Monthly | H36: No | I36: - | J36: No | K36: 0 | L36: 1 | M36: 4
A37: 3266 | B37: Amanda Nogueira | C37: Core | D37: 45383 | E37: Yes | F37: 5 | G37: Monthly | H37: No | I37: - | J37: No | K37: 0 | L37: 0 | M37: 5
A38: 3267 | B38: Bruno Cavalheiro | C38: Ultimate | D38: 45384 | E38: No | F38: 15 | G38: Quarterly | H38: Yes | I38: 30 | J38: Yes | K38: 20 | L38: 7 | M38: 58
A39: 3268 | B39: Carla Dias | C39: Standard | D39: 45385 | E39: Yes | F39: 10 | G39: Annual | H39: No | I39: - | J39: Yes | K39: 20 | L39: 10 | M39: 20
A40: 3269 | B40: Diego Fontes | C40: Core | D40: 45386 | E40: No | F40: 5 | G40: Quarterly | H40: No | I40: - | J40: No | K40: 0 | L40: 1 | M40: 4
...

Sheet C̳álculos
A1: Cálculos do Dashboard
A2: Todas as tabelas leem a aba Bases e respondem aos filtros da aba Dashboard. Texto azul = entrada manual.
A3: Filtro | B3: Seleção (Dashboard) | C3: Critério (valor na base) | E3: Rótulo no filtro | F3: Valor na base
A4: Plano | B4: ='D̳ashboard'!B7 -> Todos | C4: =IF(B4="Todos","*",B4) -> * | E4: Mensal | F4: Monthly
A5: Tipo de assinatura | B5: ='D̳ashboard'!E7 -> Todos | C5: {=IF(B5="Todos","*",IFERROR(INDEX($F$4:$F$6,MATCH(B5,$E$4:$E$6,0)),B5))} -> * | E5: Trimestral | F5: Quarterly
A6: Renovação automática | B6: ='D̳ashboard'!H7 -> Todos | C6: {=IF(B6="Todos","*",IFERROR(INDEX($F$7:$F$8,MATCH(B6,$E$7:$E$8,0)),B6))} -> * | E6: Anual | F6: Annual
E7: Sim | F7: Yes
A8: Ano de referência (meses do gráfico) | B8: 2024 | C8: Entrada manual: a base cobre jan–dez/2024. | E8: Não | F8: No
A10: T1 · Receita, cupons e ticket por plano (ignora o filtro de Plano)
A11: Plano | B11: Receita | C11: Assinantes | D11: Cupons | E11: Desconto s/ valor bruto | F11: Ticket médio | J11: Auxiliar do Top 10 (uma linha por assinatura da base)
A12: Core | B12: =SUMIFS('B̳ases'!$M$2:$M$296,'B̳ases'!$C$2:$C$296,$A12,'B̳ases'!$G$2:$G$296,$C$5,'B̳ases'!$E$2:$E$296,$C$6) -> R$ 444 | C12: =COUNTIFS('B̳ases'!$C$2:$C$296,$A12,'B̳ases'!$G$2:$G$296,$C$5,'B̳ases'!$E$2:$E$296,$C$6) -> 101 | D12: =SUMIFS('B̳ases'!$L$2:$L$296,'B̳ases'!$C$2:$C$296,$A12,'B̳ases'!$G$2:$G$296,$C$5,'B̳ases'!$E$2:$E$296,$C$6) -> R$ 61 | E12: =IFERROR(D12/(B12+D12),0) -> 12.1% | F12: =IFERROR(B12/C12,0) -> R$ 4.40 | J12: Chave (valor + desempate)
A13: Standard | B13: =SUMIFS('B̳ases'!$M$2:$M$296,'B̳ases'!$C$2:$C$296,$A13,'B̳ases'!$G$2:$G$296,$C$5,'B̳ases'!$E$2:$E$296,$C$6) -> R$ 1,801 | C13: =COUNTIFS('B̳ases'!$C$2:$C$296,$A13,'B̳ases'!$G$2:$G$296,$C$5,'B̳ases'!$E$2:$E$296,$C$6) -> 96 | D13: =SUMIFS('B̳ases'!$L$2:$L$296,'B̳ases'!$C$2:$C$296,$A13,'B̳ases'!$G$2:$G$296,$C$5,'B̳ases'!$E$2:$E$296,$C$6) -> R$ 1,079 | E13: =IFERROR(D13/(B13+D13),0) -> 37.5% | F13: =IFERROR(B13/C13,0) -> R$ 18.76 | J13: =IF(AND(OR($B$4="Todos",'B̳ases'!$C2=$B$4),OR($B$5="Todos",'B̳ases'!$G2=$C$5),OR($B$6="Todos",'B̳ases'!$E2=$C$6)),'B̳ases'!$M2+ROW()/1000000,"") -> 60.000013
A14: Ultimate | B14: =SUMIFS('B̳ases'!$M$2:$M$296,'B̳ases'!$C$2:$C$296,$A14,'B̳ases'!$G$2:$G$296,$C$5,'B̳ases'!$E$2:$E$296,$C$6) -> R$ 5,388 | C14: =COUNTIFS('B̳ases'!$C$2:$C$296,$A14,'B̳ases'!$G$2:$G$296,$C$5,'B̳ases'!$E$2:$E$296,$C$6) -> 98 | D14: =SUMIFS('B̳ases'!$L$2:$L$296,'B̳ases'!$C$2:$C$296,$A14,'B̳ases'!$G$2:$G$296,$C$5,'B̳ases'!$E$2:$E$296,$C$6) -> R$ 982 | E14: =IFERROR(D14/(B14+D14),0) -> 15.4% | F14: =IFERROR(B14/C14,0) -> R$ 54.98 | J14: =IF(AND(OR($B$4="Todos",'B̳ases'!$C3=$B$4),OR($B$5="Todos",'B̳ases'!$G3=$C$5),OR($B$6="Todos",'B̳ases'!$E3=$C$6)),'B̳ases'!$M3+ROW()/1000000,"") -> 5.000014
A15: Total | B15: =SUM(B12:B14) -> R$ 7,633 | C15: =SUM(C12:C14) -> 295 | D15: =SUM(D12:D14) -> R$ 2,122 | E15: =IFERROR(D15/(B15+D15),0) -> 21.8% | F15: =IFERROR(B15/C15,0) -> R$ 25.87 | J15: =IF(AND(OR($B$4="Todos",'B̳ases'!$C4=$B$4),OR($B$5="Todos",'B̳ases'!$G4=$C$5),OR($B$6="Todos",'B̳ases'!$E4=$C$6)),'B̳ases'!$M4+ROW()/1000000,"") -> 20.000015
J16: =IF(AND(OR($B$4="Todos",'B̳ases'!$C5=$B$4),OR($B$5="Todos",'B̳ases'!$G5=$C$5),OR($B$6="Todos",'B̳ases'!$E5=$C$6)),'B̳ases'!$M5+ROW()/1000000,"") -> 62.000016
A17: T2 · Evolução mensal (aplica todos os filtros) | J17: =IF(AND(OR($B$4="Todos",'B̳ases'!$C6=$B$4),OR($B$5="Todos",'B̳ases'!$G6=$C$5),OR($B$6="Todos",'B̳ases'!$E6=$C$6)),'B̳ases'!$M6+ROW()/1000000,"") -> 4.000017
A18: Mês | B18: Início do mês | C18: Receita | D18: Novos assinantes | J18: =IF(AND(OR($B$4="Todos",'B̳ases'!$C7=$B$4),OR($B$5="Todos",'B̳ases'!$G7=$C$5),OR($B$6="Todos",'B̳ases'!$E7=$C$6)),'B̳ases'!$M7+ROW()/1000000,"") -> 28.000018
A19: Jan | B19: =DATE($B$8,1,1) -> 01/2024 | C19: =SUMIFS('B̳ases'!$M$2:$M$296,'B̳ases'!$D$2:$D$296,">="&B19,'B̳ases'!$D$2:$D$296,"<"&DATE(YEAR(B19),MONTH(B19)+1,1),'B̳ases'!$C$2:$C$296,$C$4,'B̳ases'!$G$2:$G$296,$C$5,'B̳ases'!$E$2:$E$296,$C$6) -> R$ 65 | D19: =COUNTIFS('B̳ases'!$D$2:$D$296,">="&B19,'B̳ases'!$D$2:$D$296,"<"&DATE(YEAR(B19),MONTH(B19)+1,1),'B̳ases'!$C$2:$C$296,$C$4,'B̳ases'!$G$2:$G$296,$C$5,'B̳ases'!$E$2:$E$296,$C$6) -> 2 | J19: =IF(AND(OR($B$4="Todos",'B̳ases'!$C8=$B$4),OR($B$5="Todos",'B̳ases'!$G8=$C$5),OR($B$6="Todos",'B̳ases'!$E8=$C$6)),'B̳ases'!$M8+ROW()/1000000,"") -> 55.000019
A20: Fev | B20: =DATE($B$8,2,1) -> 02/2024 | C20: =SUMIFS('B̳ases'!$M$2:$M$296,'B̳ases'!$D$2:$D$296,">="&B20,'B̳ases'!$D$2:$D$296,"<"&DATE(YEAR(B20),MONTH(B20)+1,1),'B̳ases'!$C$2:$C$296,$C$4,'B̳ases'!$G$2:$G$296,$C$5,'B̳ases'!$E$2:$E$296,$C$6) -> R$ 82 | D20: =COUNTIFS('B̳ases'!$D$2:$D$296,">="&B20,'B̳ases'!$D$2:$D$296,"<"&DATE(YEAR(B20),MONTH(B20)+1,1),'B̳ases'!$C$2:$C$296,$C$4,'B̳ases'!$G$2:$G$296,$C$5,'B̳ases'!$E$2:$E$296,$C$6) -> 2 | J20: =IF(AND(OR($B$4="Todos",'B̳ases'!$C9=$B$4),OR($B$5="Todos",'B̳ases'!$G9=$C$5),OR($B$6="Todos",'B̳ases'!$E9=$C$6)),'B̳ases'!$M9+ROW()/1000000,"") -> 5.000020
A21: Mar | B21: =DATE($B$8,3,1) -> 03/2024 | C21: =SUMIFS('B̳ases'!$M$2:$M$296,'B̳ases'!$D$2:$D$296,">="&B21,'B̳ases'!$D$2:$D$296,"<"&DATE(YEAR(B21),MONTH(B21)+1,1),'B̳ases'!$C$2:$C$296,$C$4,'B̳ases'!$G$2:$G$296,$C$5,'B̳ases'!$E$2:$E$296,$C$6) -> R$ 801 | D21: =COUNTIFS('B̳ases'!$D$2:$D$296,">="&B21,'B̳ases'!$D$2:$D$296,"<"&DATE(YEAR(B21),MONTH(B21)+1,1),'B̳ases'!$C$2:$C$296,$C$4,'B̳ases'!$G$2:$G$296,$C$5,'B̳ases'!$E$2:$E$296,$C$6) -> 31 | J21: =IF(AND(OR($B$4="Todos",'B̳ases'!$C10=$B$4),OR($B$5="Todos",'B̳ases'!$G10=$C$5),OR($B$6="Todos",'B̳ases'!$E10=$C$6)),'B̳ases'!$M10+ROW()/1000000,"") -> 60.000021
A22: Abr | B22: =DATE($B$8,4,1) -> 04/2024 | C22: =SUMIFS('B̳ases'!$M$2:$M$296,'B̳ases'!$D$2:$D$296,">="&B22,'B̳ases'!$D$2:$D$296,"<"&DATE(YEAR(B22),MONTH(B22)+1,1),'B̳ases'!$C$2:$C$296,$C$4,'B̳ases'!$G$2:$G$296,$C$5,'B̳ases'!$E$2:$E$296,$C$6) -> R$ 782 | D22: =COUNTIFS('B̳ases'!$D$2:$D$296,">="&B22,'B̳ases'!$D$2:$D$296,"<"&DATE(YEAR(B22),MONTH(B22)+1,1),'B̳ases'!$C$2:$C$296,$C$4,'B̳ases'!$G$2:$G$296,$C$5,'B̳ases'!$E$2:$E$296,$C$6) -> 30 | J22: =IF(AND(OR($B$4="Todos",'B̳ases'!$C11=$B$4),OR($B$5="Todos",'B̳ases'!$G11=$C$5),OR($B$6="Todos",'B̳ases'!$E11=$C$6)),'B̳ases'!$M11+ROW()/1000000,"") -> 15.000022
A23: Mai | B23: =DATE($B$8,5,1) -> 05/2024 | C23: =SUMIFS('B̳ases'!$M$2:$M$296,'B̳ases'!$D$2:$D$296,">="&B23,'B̳ases'!$D$2:$D$296,"<"&DATE(YEAR(B23),MONTH(B23)+1,1),'B̳ases'!$C$2:$C$296,$C$4,'B̳ases'!$G$2:$G$296,$C$5,'B̳ases'!$E$2:$E$296,$C$6) -> R$ 777 | D23: =COUNTIFS('B̳ases'!$D$2:$D$296,">="&B23,'B̳ases'!$D$2:$D$296,"<"&DATE(YEAR(B23),MONTH(B23)+1,1),'B̳ases'!$C$2:$C$296,$C$4,'B̳ases'!$G$2:$G$296,$C$5,'B̳ases'!$E$2:$E$296,$C$6) -> 31 | J23: =IF(AND(OR($B$4="Todos",'B̳ases'!$C12=$B$4),OR($B$5="Todos",'B̳ases'!$G12=$C$5),OR($B$6="Todos",'B̳ases'!$E12=$C$6)),'B̳ases'!$M12+ROW()/1000000,"") -> 4.000023
A24: Jun | B24: =DATE($B$8,6,1) -> 06/2024 | C24: =SUMIFS('B̳ases'!$M$2:$M$296,'B̳ases'!$D$2:$D$296,">="&B24,'B̳ases'!$D$2:$D$296,"<"&DATE(YEAR(B24),MONTH(B24)+1,1),'B̳ases'!$C$2:$C$296,$C$4,'B̳ases'!$G$2:$G$296,$C$5,'B̳ases'!$E$2:$E$296,$C$6) -> R$ 770 | D24: =COUNTIFS('B̳ases'!$D$2:$D$296,">="&B24,'B̳ases'!$D$2:$D$296,"<"&DATE(YEAR(B24),MONTH(B24)+1,1),'B̳ases'!$C$2:$C$296,$C$4,'B̳ases'!$G$2:$G$296,$C$5,'B̳ases'!$E$2:$E$296,$C$6) -> 30 | J24: =IF(AND(OR($B$4="Todos",'B̳ases'!$C13=$B$4),OR($B$5="Todos",'B̳ases'!$G13=$C$5),OR($B$6="Todos",'B̳ases'!$E13=$C$6)),'B̳ases'!$M13+ROW()/1000000,"") -> 45.000024
A25: Jul | B25: =DATE($B$8,7,1) -> 07/2024 | C25: =SUMIFS('B̳ases'!$M$2:$M$296,'B̳ases'!$D$2:$D$296,">="&B25,'B̳ases'!$D$2:$D$296,"<"&DATE(YEAR(B25),MONTH(B25)+1,1),'B̳ases'!$C$2:$C$296,$C$4,'B̳ases'!$G$2:$G$296,$C$5,'B̳ases'!$E$2:$E$296,$C$6) -> R$ 784 | D25: =COUNTIFS('B̳ases'!$D$2:$D$296,">="&B25,'B̳ases'!$D$2:$D$296,"<"&DATE(YEAR(B25),MONTH(B25)+1,1),'B̳ases'!$C$2:$C$296,$C$4,'B̳ases'!$G$2:$G$296,$C$5,'B̳ases'!$E$2:$E$296,$C$6) -> 31 | J25: =IF(AND(OR($B$4="Todos",'B̳ases'!$C14=$B$4),OR($B$5="Todos",'B̳ases'!$G14=$C$5),OR($B$6="Todos",'B̳ases'!$E14=$C$6)),'B̳ases'!$M14+ROW()/1000000,"") -> 20.000025
A26: Ago | B26: =DATE($B$8,8,1) -> 08/2024 | C26: =SUMIFS('B̳ases'!$M$2:$M$296,'B̳ases'!$D$2:$D$296,">="&B26,'B̳ases'!$D$2:$D$296,"<"&DATE(YEAR(B26),MONTH(B26)+1,1),'B̳ases'!$C$2:$C$296,$C$4,'B̳ases'!$G$2:$G$296,$C$5,'B̳ases'!$E$2:$E$296,$C$6) -> R$ 787 | D26: =COUNTIFS('B̳ases'!$D$2:$D$296,">="&B26,'B̳ases'!$D$2:$D$296,"<"&DATE(YEAR(B26),MONTH(B26)+1,1),'B̳ases'!$C$2:$C$296,$C$4,'B̳ases'!$G$2:$G$296,$C$5,'B̳ases'!$E$2:$E$296,$C$6) -> 31 | J26: =IF(AND(OR($B$4="Todos",'B̳ases'!$C15=$B$4),OR($B$5="Todos",'B̳ases'!$G15=$C$5),OR($B$6="Todos",'B̳ases'!$E15=$C$6)),'B̳ases'!$M15+ROW()/1000000,"") -> 5.000026
A27: Set | B27: =DATE($B$8,9,1) -> 09/2024 | C27: =SUMIFS('B̳ases'!$M$2:$M$296,'B̳ases'!$D$2:$D$296,">="&B27,'B̳ases'!$D$2:$D$296,"<"&DATE(YEAR(B27),MONTH(B27)+1,1),'B̳ases'!$C$2:$C$296,$C$4,'B̳ases'!$G$2:$G$296,$C$5,'B̳ases'!$E$2:$E$296,$C$6) -> R$ 780 | D27: =COUNTIFS('B̳ases'!$D$2:$D$296,">="&B27,'B̳ases'!$D$2:$D$296,"<"&DATE(YEAR(B27),MONTH(B27)+1,1),'B̳ases'!$C$2:$C$296,$C$4,'B̳ases'!$G$2:$G$296,$C$5,'B̳ases'!$E$2:$E$296,$C$6) -> 30 | J27: =IF(AND(OR($B$4="Todos",'B̳ases'!$C16=$B$4),OR($B$5="Todos",'B̳ases'!$G16=$C$5),OR($B$6="Todos",'B̳ases'!$E16=$C$6)),'B̳ases'!$M16+ROW()/1000000,"") -> 57.000027
A28: Out | B28: =DATE($B$8,10,1) -> 10/2024 | C28: =SUMIFS('B̳ases'!$M$2:$M$296,'B̳ases'!$D$2:$D$296,">="&B28,'B̳ases'!$D$2:$D$296,"<"&DATE(YEAR(B28),MONTH(B28)+1,1),'B̳ases'!$C$2:$C$296,$C$4,'B̳ases'!$G$2:$G$296,$C$5,'B̳ases'!$E$2:$E$296,$C$6) -> R$ 832 | D28: =COUNTIFS('B̳ases'!$D$2:$D$296,">="&B28,'B̳ases'!$D$2:$D$296,"<"&DATE(YEAR(B28),MONTH(B28)+1,1),'B̳ases'!$C$2:$C$296,$C$4,'B̳ases'!$G$2:$G$296,$C$5,'B̳ases'!$E$2:$E$296,$C$6) -> 31 | J28: =IF(AND(OR($B$4="Todos",'B̳ases'!$C17=$B$4),OR($B$5="Todos",'B̳ases'!$G17=$C$5),OR($B$6="Todos",'B̳ases'!$E17=$C$6)),'B̳ases'!$M17+ROW()/1000000,"") -> 18.000028
A29: Nov | B29: =DATE($B$8,11,1) -> 11/2024 | C29: =SUMIFS('B̳ases'!$M$2:$M$296,'B̳ases'!$D$2:$D$296,">="&B29,'B̳ases'!$D$2:$D$296,"<"&DATE(YEAR(B29),MONTH(B29)+1,1),'B̳ases'!$C$2:$C$296,$C$4,'B̳ases'!$G$2:$G$296,$C$5,'B̳ases'!$E$2:$E$296,$C$6) -> R$ 784 | D29: =COUNTIFS('B̳ases'!$D$2:$D$296,">="&B29,'B̳ases'!$D$2:$D$296,"<"&DATE(YEAR(B29),MONTH(B29)+1,1),'B̳ases'!$C$2:$C$296,$C$4,'B̳ases'!$G$2:$G$296,$C$5,'B̳ases'!$E$2:$E$296,$C$6) -> 30 | J29: =IF(AND(OR($B$4="Todos",'B̳ases'!$C18=$B$4),OR($B$5="Todos",'B̳ases'!$G18=$C$5),OR($B$6="Todos",'B̳ases'!$E18=$C$6)),'B̳ases'!$M18+ROW()/1000000,"") -> 3.000029
A30: Dez | B30: =DATE($B$8,12,1) -> 12/2024 | C30: =SUMIFS('B̳ases'!$M$2:$M$296,'B̳ases'!$D$2:$D$296,">="&B30,'B̳ases'!$D$2:$D$296,"<"&DATE(YEAR(B30),MONTH(B30)+1,1),'B̳ases'!$C$2:$C$296,$C$4,'B̳ases'!$G$2:$G$296,$C$5,'B̳ases'!$E$2:$E$296,$C$6) -> R$ 389 | D30: =COUNTIFS('B̳ases'!$D$2:$D$296,">="&B30,'B̳ases'!$D$2:$D$296,"<"&DATE(YEAR(B30),MONTH(B30)+1,1),'B̳ases'!$C$2:$C$296,$C$4,'B̳ases'!$G$2:$G$296,$C$5,'B̳ases'!$E$2:$E$296,$C$6) -> 16 | J30: =IF(AND(OR($B$4="Todos",'B̳ases'!$C19=$B$4),OR($B$5="Todos",'B̳ases'!$G19=$C$5),OR($B$6="Todos",'B̳ases'!$E19=$C$6)),'B̳ases'!$M19+ROW()/1000000,"") -> 58.000030
J31: =IF(AND(OR($B$4="Todos",'B̳ases'!$C20=$B$4),OR($B$5="Todos",'B̳ases'!$G20=$C$5),OR($B$6="Todos",'B̳ases'!$E20=$C$6)),'B̳ases'!$M20+ROW()/1000000,"") -> 25.000031
A32: T3 · Mix por tipo de assinatura (ignora o filtro de Tipo) | J32: =IF(AND(OR($B$4="Todos",'B̳ases'!$C21=$B$4),OR($B$5="Todos",'B̳ases'!$G21=$C$5),OR($B$6="Todos",'B̳ases'!$E21=$C$6)),'B̳ases'!$M21+ROW()/1000000,"") -> 5.000032
A33: Tipo | B33: Valor na base | C33: Assinantes | D33: Receita | J33: =IF(AND(OR($B$4="Todos",'B̳ases'!$C22=$B$4),OR($B$5="Todos",'B̳ases'!$G22=$C$5),OR($B$6="Todos",'B̳ases'!$E22=$C$6)),'B̳ases'!$M22+ROW()/1000000,"") -> 62.000033
A34: Mensal | B34: Monthly | C34: =COUNTIFS('B̳ases'!$G$2:$G$296,$B34,'B̳ases'!$C$2:$C$296,$C$4,'B̳ases'!$E$2:$E$296,$C$6) -> 139 | D34: =SUMIFS('B̳ases'!$M$2:$M$296,'B̳ases'!$G$2:$G$296,$B34,'B̳ases'!$C$2:$C$296,$C$4,'B̳ases'!$E$2:$E$296,$C$6) -> R$ 3,571 | J34: =IF(AND(OR($B$4="Todos",'B̳ases'!$C23=$B$4),OR($B$5="Todos",'B̳ases'!$G23=$C$5),OR($B$6="Todos",'B̳ases'!$E23=$C$6)),'B̳ases'!$M23+ROW()/1000000,"") -> 15.000034
A35: Trimestral | B35: Quarterly | C35: =COUNTIFS('B̳ases'!$G$2:$G$296,$B35,'B̳ases'!$C$2:$C$296,$C$4,'B̳ases'!$E$2:$E$296,$C$6) -> 85 | D35: =SUMIFS('B̳ases'!$M$2:$M$296,'B̳ases'!$G$2:$G$296,$B35,'B̳ases'!$C$2:$C$296,$C$4,'B̳ases'!$E$2:$E$296,$C$6) -> R$ 2,308 | J35: =IF(AND(OR($B$4="Todos",'B̳ases'!$C24=$B$4),OR($B$5="Todos",'B̳ases'!$G24=$C$5),OR($B$6="Todos",'B̳ases'!$E24=$C$6)),'B̳ases'!$M24+ROW()/1000000,"") -> 4.000035
A36: Anual | B36: Annual | C36: =COUNTIFS('B̳ases'!$G$2:$G$296,$B36,'B̳ases'!$C$2:$C$296,$C$4,'B̳ases'!$E$2:$E$296,$C$6) -> 71 | D36: =SUMIFS('B̳ases'!$M$2:$M$296,'B̳ases'!$G$2:$G$296,$B36,'B̳ases'!$C$2:$C$296,$C$4,'B̳ases'!$E$2:$E$296,$C$6) -> R$ 1,754 | J36: =IF(AND(OR($B$4="Todos",'B̳ases'!$C25=$B$4),OR($B$5="Todos",'B̳ases'!$G25=$C$5),OR($B$6="Todos",'B̳ases'!$E25=$C$6)),'B̳ases'!$M25+ROW()/1000000,"") -> 45.000036
J37: =IF(AND(OR($B$4="Todos",'B̳ases'!$C26=$B$4),OR($B$5="Todos",'B̳ases'!$G26=$C$5),OR($B$6="Todos",'B̳ases'!$E26=$C$6)),'B̳ases'!$M26+ROW()/1000000,"") -> 20.000037
A38: T4 · Renovação automática por plano (ignora Plano e Renovação) | J38: =IF(AND(OR($B$4="Todos",'B̳ases'!$C27=$B$4),OR($B$5="Todos",'B̳ases'!$G27=$C$5),OR($B$6="Todos",'B̳ases'!$E27=$C$6)),'B̳ases'!$M27+ROW()/1000000,"") -> 5.000038
A39: Plano | B39: Com renovação | C39: Sem renovação | J39: =IF(AND(OR($B$4="Todos",'B̳ases'!$C28=$B$4),OR($B$5="Todos",'B̳ases'!$G28=$C$5),OR($B$6="Todos",'B̳ases'!$E28=$C$6)),'B̳ases'!$M28+ROW()/1000000,"") -> 60.000039
A40: Core | B40: =COUNTIFS('B̳ases'!$C$2:$C$296,$A40,'B̳ases'!$E$2:$E$296,"Yes",'B̳ases'!$G$2:$G$296,$C$5) -> 51 | C40: =COUNTIFS('B̳ases'!$C$2:$C$296,$A40,'B̳ases'!$E$2:$E$296,"No",'B̳ases'!$G$2:$G$296,$C$5) -> 50 | J40: =IF(AND(OR($B$4="Todos",'B̳ases'!$C29=$B$4),OR($B$5="Todos",'B̳ases'!$G29=$C$5),OR($B$6="Todos",'B̳ases'!$E29=$C$6)),'B̳ases'!$M29+ROW()/1000000,"") -> 15.000040
A41: Standard | B41: =COUNTIFS('B̳ases'!$C$2:$C$296,$A41,'B̳ases'!$E$2:$E$296,"Yes",'B̳ases'!$G$2:$G$296,$C$5) -> 49 | C41: =COUNTIFS('B̳ases'!$C$2:$C$296,$A41,'B̳ases'!$E$2:$E$296,"No",'B̳ases'!$G$2:$G$296,$C$5) -> 47 | J41: =IF(AND(OR($B$4="Todos",'B̳ases'!$C30=$B$4),OR($B$5="Todos",'B̳ases'!$G30=$C$5),OR($B$6="Todos",'B̳ases'!$E30=$C$6)),'B̳ases'!$M30+ROW()/1000000,"") -> 4.000041
...

Sheet D̳ashboard
E2: Dashboard de Vendas · Assinaturas
E3: ="Período da base: "&TEXT(MIN('B̳ases'!$D$2:$D$296),"dd/mm/yyyy")&" a "&TEXT(MAX('B̳ases'!$D$2:$D$296),"dd/mm/yyyy")&" · "&TEXT(COUNTA('B̳ases'!$A$2:$A$296),"#,##0")&" assinaturas" -> Período da base: 01/01/2024 a 16/12/2024 · 295 assinaturas
B6: PLANO | E6: TIPO DE ASSINATURA | H6: RENOVAÇÃO AUTOMÁTICA
B7: Todos | E7: Todos | H7: Todos | K7: ◄ Escolha nos filtros: indicadores e gráficos atualizam sozinhos.
B9: RECEITA TOTAL | E9: ASSINANTES | H9: TICKET MÉDIO | K9: CUPONS CONCEDIDOS | N9: RENOVAÇÃO AUTOMÁTICA
B10: ='C̳álculos'!B52 -> R$ 7,633 | E10: ='C̳álculos'!B53 -> 295 | H10: ='C̳álculos'!B54 -> R$ 25.87 | K10: ='C̳álculos'!B55 -> R$ 2,122 | N10: ='C̳álculos'!B57 -> 50.2%
B12: ="soma do valor total das assinaturas" -> soma do valor total das assinaturas | E12: ="assinaturas na seleção" -> assinaturas na seleção | H12: ="receita ÷ assinantes" -> receita ÷ assinantes | K12: =TEXT('C̳álculos'!B56,"0%")&" do valor bruto" -> 22% do valor bruto | N12: ="assinaturas com renovação ativa" -> assinaturas com renovação ativa
G46: Top 10 assinantes por valor
G47: # | H47: Assinante | K47: Plano | M47: Tipo | O47: Valor total
G48: =IF('C̳álculos'!D73="","",1) -> 1 | H48: ='C̳álculos'!D73 -> Carla Siqueira | K48: ='C̳álculos'!E73 -> Ultimate | M48: ='C̳álculos'!F73 -> Mensal | O48: ='C̳álculos'!G73 -> R$ 62
G49: =IF('C̳álculos'!D74="","",2) -> 2 | H49: ='C̳álculos'!D74 -> Natália Castro | K49: ='C̳álculos'!E74 -> Ultimate | M49: ='C̳álculos'!F74 -> Anual | O49: ='C̳álculos'!G74 -> R$ 62
G50: =IF('C̳álculos'!D75="","",3) -> 3 | H50: ='C̳álculos'!D75 -> Elisa Correia | K50: ='C̳álculos'!E75 -> Ultimate | M50: ='C̳álculos'!F75 -> Mensal | O50: ='C̳álculos'!G75 -> R$ 62
G51: =IF('C̳álculos'!D76="","",4) -> 4 | H51: ='C̳álculos'!D76 -> Natália Soares | K51: ='C̳álculos'!E76 -> Ultimate | M51: ='C̳álculos'!F76 -> Anual | O51: ='C̳álculos'!G76 -> R$ 62
G52: =IF('C̳álculos'!D77="","",5) -> 5 | H52: ='C̳álculos'!D77 -> Elisa Neves | K52: ='C̳álculos'!E77 -> Ultimate | M52: ='C̳álculos'!F77 -> Mensal | O52: ='C̳álculos'!G77 -> R$ 62
G53: =IF('C̳álculos'!D78="","",6) -> 6 | H53: ='C̳álculos'!D78 -> Patrícia Leite | K53: ='C̳álculos'!E78 -> Ultimate | M53: ='C̳álculos'!F78 -> Anual | O53: ='C̳álculos'!G78 -> R$ 62
G54: =IF('C̳álculos'!D79="","",7) -> 7 | H54: ='C̳álculos'!D79 -> Gabriel Santos | K54: ='C̳álculos'!E79 -> Ultimate | M54: ='C̳álculos'!F79 -> Mensal | O54: ='C̳álculos'!G79 -> R$ 62
G55: =IF('C̳álculos'!D80="","",8) -> 8 | H55: ='C̳álculos'!D80 -> Joana Silveira | K55: ='C̳álculos'!E80 -> Ultimate | M55: ='C̳álculos'!F80 -> Anual | O55: ='C̳álculos'!G80 -> R$ 62
G56: =IF('C̳álculos'!D81="","",9) -> 9 | H56: ='C̳álculos'!D81 -> André Lopes | K56: ='C̳álculos'!E81 -> Ultimate | M56: ='C̳álculos'!F81 -> Mensal | O56: ='C̳álculos'!G81 -> R$ 62
G57: =IF('C̳álculos'!D82="","",10) -> 10 | H57: ='C̳álculos'!D82 -> João Carvalho | K57: ='C̳álculos'!E82 -> Ultimate | M57: ='C̳álculos'!F82 -> Mensal | O57: ='C̳álculos'!G82 -> R$ 62
G59: Valor total = plano + add-ons − cupom. Respeita todos os filtros.
B62: Receita por plano × tipo de assinatura | J62: Oportunidades de ação
B63: Plano | D63: Mensal | E63: Trimestral | F63: Anual | G63: Total | J63: Assinantes sem renovação automática | N63: ='C̳álculos'!B58 -> 147
B64: ='C̳álculos'!A66 -> Core | D64: ='C̳álculos'!B66 -> R$ 192 | E64: ='C̳álculos'!C66 -> R$ 132 | F64: ='C̳álculos'!D66 -> R$ 120 | G64: ='C̳álculos'!E66 -> R$ 444 | J64: Receita desses assinantes | N64: ='C̳álculos'!B59 -> R$ 3,847
B65: ='C̳álculos'!A67 -> Standard | D65: ='C̳álculos'!B67 -> R$ 958 | E65: ='C̳álculos'!C67 -> R$ 395 | F65: ='C̳álculos'!D67 -> R$ 448 | G65: ='C̳álculos'!E67 -> R$ 1,801 | J65: Assinantes no plano mensal | N65: ='C̳álculos'!B60 -> 139
B66: ='C̳álculos'!A68 -> Ultimate | D66: ='C̳álculos'!B68 -> R$ 2,421 | E66: ='C̳álculos'!C68 -> R$ 1,781 | F66: ='C̳álculos'!D68 -> R$ 1,186 | G66: ='C̳álculos'!E68 -> R$ 5,388 | J66: Receita desses assinantes | N66: ='C̳álculos'!B61 -> R$ 3,571
B67: ='C̳álculos'!A69 -> Total | D67: ='C̳álculos'!B69 -> R$ 3,571 | E67: ='C̳álculos'!C69 -> R$ 2,308 | F67: ='C̳álculos'!D69 -> R$ 1,754 | G67: ='C̳álculos'!E69 -> R$ 7,633 | J67: Públicos para retenção e migração para planos mais longos.
B69: Fonte: aba Bases. Os gráficos por plano, tipo e renovação ignoram o próprio filtro para continuar mostrando a comparação. Regras e fórmulas na aba Cálculos.
